Workbook

Sheet Summary
A1: Car | B1: Chassis No. | C1: Operating Status | D1: Engine No. | E1: Missing Items
A2: Car 1 - 00569 | B2: =IF('Car 1 - 00569'!B1="","",'Car 1 - 00569'!B1) -> MD2A68CX5TWb00569 | C2: =IF('Car 1 - 00569'!B3="","",'Car 1 - 00569'!B3) | D2: =IF('Car 1 - 00569'!B2="","",'Car 1 - 00569'!B2) -> BFXWTB23429 | E2: =COUNTA('Car 1 - 00569'!$B$7:$B$300) -> 10
A3: Car 2 - 01124 | B3: =IF('Car 2 - 01124'!B1="","",'Car 2 - 01124'!B1) -> MD2A68CX5TWK01124 | C3: =IF('Car 2 - 01124'!B3="","",'Car 2 - 01124'!B3) -> Accident - at the bodywork and paint shop | D3: =IF('Car 2 - 01124'!B2="","",'Car 2 - 01124'!B2) | E3: =COUNTA('Car 2 - 01124'!$B$8:$B$300) -> 27
A4: Car 3 - 00133 | B4: =IF('Car 3 - 00133'!B1="","",'Car 3 - 00133'!B1) -> MD2A68CX4TWM00133 | C4: =IF('Car 3 - 00133'!B3="","",'Car 3 - 00133'!B3) -> Not running - needs ECU inspection | D4: =IF('Car 3 - 00133'!B2="","",'Car 3 - 00133'!B2) -> BXXWTM21238 | E4: =COUNTA('Car 3 - 00133'!$B$8:$B$300) -> 18
A5: Car 4 - 00679 | B5: =IF('Car 4 - 00679'!B1="","",'Car 4 - 00679'!B1) -> MD2A68CX1WTB00679 | C5: =IF('Car 4 - 00679'!B3="","",'Car 4 - 00679'!B3) -> Accident - at the bodywork and paint shop | D5: =IF('Car 4 - 00679'!B2="","",'Car 4 - 00679'!B2) -> BFXWTB23607 | E5: =COUNTA('Car 4 - 00679'!$B$8:$B$300) -> 12
A6: Car 5 - 00557 | B6: =IF('Car 5 - 00557'!B1="","",'Car 5 - 00557'!B1) -> MD2A68CX9TWB00557 | C6: =IF('Car 5 - 00557'!B3="","",'Car 5 - 00557'!B3) -> Not running | D6: =IF('Car 5 - 00557'!B2="","",'Car 5 - 00557'!B2) -> Engine dismantled | E6: =COUNTA('Car 5 - 00557'!$B$8:$B$300) -> 32
A7: Car 6 - 00663 | B7: =IF('Car 6 - 00663'!B1="","",'Car 6 - 00663'!B1) -> MD2A68CX8TWB00663 | C7: =IF('Car 6 - 00663'!B3="","",'Car 6 - 00663'!B3) -> Running | D7: =IF('Car 6 - 00663'!B2="","",'Car 6 - 00663'!B2) -> BFXWTB23627 | E7: =COUNTA('Car 6 - 00663'!$B$8:$B$300) -> 3
A8: Car 7 - 00680 | B8: =IF('Car 7 - 00680'!B1="","",'Car 7 - 00680'!B1) -> MD2A68CX8TWB00680 | C8: =IF('Car 7 - 00680'!B3="","",'Car 7 - 00680'!B3) -> Not running | D8: =IF('Car 7 - 00680'!B2="","",'Car 7 - 00680'!B2) -> BFXWTB23163 | E8: =COUNTA('Car 7 - 00680'!$B$8:$B$300) -> 11
A9: Car 8 - 00523 | B9: =IF('Car 8 - 00523'!B1="","",'Car 8 - 00523'!B1) -> MD2A68CX3TWB00523 | C9: =IF('Car 8 - 00523'!B3="","",'Car 8 - 00523'!B3) -> Running | D9: =IF('Car 8 - 00523'!B2="","",'Car 8 - 00523'!B2) -> BFXWTB2345 | E9: =COUNTA('Car 8 - 00523'!$B$8:$B$300) -> 4
A10: Car 9 - 00097 | B10: =IF('Car 9 - 00097'!B1="","",'Car 9 - 00097'!B1) -> MD2A68CX4TWM00097 | C10: =IF('Car 9 - 00097'!B3="","",'Car 9 - 00097'!B3) -> Engine is at the service center | D10: =IF('Car 9 - 00097'!B2="","",'Car 9 - 00097'!B2) -> BFXWTM21314 | E10: =COUNTA('Car 9 - 00097'!$B$8:$B$300) -> 34
A11: Car 10 - 01352 | B11: =IF('Car 10 - 01352'!B1="","",'Car 10 - 01352'!B1) -> MD2A68CX7TWK01352 | C11: =IF('Car 10 - 01352'!B3="","",'Car 10 - 01352'!B3) -> Accident | D11: =IF('Car 10 - 01352'!B2="","",'Car 10 - 01352'!B2) -> BFXWTK20030 | E11: =COUNTA('Car 10 - 01352'!$B$8:$B$300) -> 33
A12: Total | E12: =SUM(E2:E11) -> 184
A14: Total Required Parts - All Cars (by Part No.)
A15: Part Name | B15: Part No. | C15: Arabic Name | D15: Car 1 | E15: Car 2 | F15: Car 3 | G15: Car 4 | H15: Car 5 | I15: Car 6 | J15: Car 7 | K15: Car 8 | L15: Car 9 | M15: Car 10 | N15: Total
A16: KIT SET LOCK LHD | B16: 36BF0024 | C16: ضمن: كالون باب امامي شمال | D16: =SUMIF('Car 1 - 00569'!$D$7:$D$300,$B16,'Car 1 - 00569'!$E$7:$E$300)+COUNTIFS('Car 1 - 00569'!$D$7:$D$300,$B16,'Car 1 - 00569'!$E$7:$E$300,"") -> 0 | E16: =SUMIF('Car 2 - 01124'!$D$7:$D$300,$B16,'Car 2 - 01124'!$E$7:$E$300)+COUNTIFS('Car 2 - 01124'!$D$7:$D$300,$B16,'Car 2 - 01124'!$E$7:$E$300,"") -> 0 | F16: =SUMIF('Car 3 - 00133'!$D$7:$D$300,$B16,'Car 3 - 00133'!$E$7:$E$300)+COUNTIFS('Car 3 - 00133'!$D$7:$D$300,$B16,'Car 3 - 00133'!$E$7:$E$300,"") -> 0 | G16: =SUMIF('Car 4 - 00679'!$D$7:$D$300,$B16,'Car 4 - 00679'!$E$7:$E$300)+COUNTIFS('Car 4 - 00679'!$D$7:$D$300,$B16,'Car 4 - 00679'!$E$7:$E$300,"") -> 0 | H16: =SUMIF('Car 5 - 00557'!$D$7:$D$300,$B16,'Car 5 - 00557'!$E$7:$E$300)+COUNTIFS('Car 5 - 00557'!$D$7:$D$300,$B16,'Car 5 - 00557'!$E$7:$E$300,"") -> 0 | I16: =SUMIF('Car 6 - 00663'!$D$7:$D$300,$B16,'Car 6 - 00663'!$E$7:$E$300)+COUNTIFS('Car 6 - 00663'!$D$7:$D$300,$B16,'Car 6 - 00663'!$E$7:$E$300,"") -> 0 | J16: =SUMIF('Car 7 - 00680'!$D$7:$D$300,$B16,'Car 7 - 00680'!$E$7:$E$300)+COUNTIFS('Car 7 - 00680'!$D$7:$D$300,$B16,'Car 7 - 00680'!$E$7:$E$300,"") -> 0 | K16: =SUMIF('Car 8 - 00523'!$D$7:$D$300,$B16,'Car 8 - 00523'!$E$7:$E$300)+COUNTIFS('Car 8 - 00523'!$D$7:$D$300,$B16,'Car 8 - 00523'!$E$7:$E$300,"") -> 0 | L16: =SUMIF('Car 9 - 00097'!$D$7:$D$300,$B16,'Car 9 - 00097'!$E$7:$E$300)+COUNTIFS('Car 9 - 00097'!$D$7:$D$300,$B16,'Car 9 - 00097'!$E$7:$E$300,"") -> 0 | M16: =SUMIF('Car 10 - 01352'!$D$7:$D$300,$B16,'Car 10 - 01352'!$E$7:$E$300)+COUNTIFS('Car 10 - 01352'!$D$7:$D$300,$B16,'Car 10 - 01352'!$E$7:$E$300,"") -> 1 | N16: =SUM(D16:M16) -> 1
A17: ASSEMBLY REAR DOOR COMP RH WHITE | B17: 52BF0102 | C17: باب خلفي يمين + فريم + زجاج + جوانة + فبرة زجاج | D17: =SUMIF('Car 1 - 00569'!$D$7:$D$300,$B17,'Car 1 - 00569'!$E$7:$E$300)+COUNTIFS('Car 1 - 00569'!$D$7:$D$300,$B17,'Car 1 - 00569'!$E$7:$E$300,"") -> 0 | E17: =SUMIF('Car 2 - 01124'!$D$7:$D$300,$B17,'Car 2 - 01124'!$E$7:$E$300)+COUNTIFS('Car 2 - 01124'!$D$7:$D$300,$B17,'Car 2 - 01124'!$E$7:$E$300,"") -> 1 | F17: =SUMIF('Car 3 - 00133'!$D$7:$D$300,$B17,'Car 3 - 00133'!$E$7:$E$300)+COUNTIFS('Car 3 - 00133'!$D$7:$D$300,$B17,'Car 3 - 00133'!$E$7:$E$300,"") -> 0 | G17: =SUMIF('Car 4 - 00679'!$D$7:$D$300,$B17,'Car 4 - 00679'!$E$7:$E$300)+COUNTIFS('Car 4 - 00679'!$D$7:$D$300,$B17,'Car 4 - 00679'!$E$7:$E$300,"") -> 1 | H17: =SUMIF('Car 5 - 00557'!$D$7:$D$300,$B17,'Car 5 - 00557'!$E$7:$E$300)+COUNTIFS('Car 5 - 00557'!$D$7:$D$300,$B17,'Car 5 - 00557'!$E$7:$E$300,"") -> 1 | I17: =SUMIF('Car 6 - 00663'!$D$7:$D$300,$B17,'Car 6 - 00663'!$E$7:$E$300)+COUNTIFS('Car 6 - 00663'!$D$7:$D$300,$B17,'Car 6 - 00663'!$E$7:$E$300,"") -> 0 | J17: =SUMIF('Car 7 - 00680'!$D$7:$D$300,$B17,'Car 7 - 00680'!$E$7:$E$300)+COUNTIFS('Car 7 - 00680'!$D$7:$D$300,$B17,'Car 7 - 00680'!$E$7:$E$300,"") -> 0 | K17: =SUMIF('Car 8 - 00523'!$D$7:$D$300,$B17,'Car 8 - 00523'!$E$7:$E$300)+COUNTIFS('Car 8 - 00523'!$D$7:$D$300,$B17,'Car 8 - 00523'!$E$7:$E$300,"") -> 0 | L17: =SUMIF('Car 9 - 00097'!$D$7:$D$300,$B17,'Car 9 - 00097'!$E$7:$E$300)+COUNTIFS('Car 9 - 00097'!$D$7:$D$300,$B17,'Car 9 - 00097'!$E$7:$E$300,"") -> 1 | M17: =SUMIF('Car 10 - 01352'!$D$7:$D$300,$B17,'Car 10 - 01352'!$E$7:$E$300)+COUNTIFS('Car 10 - 01352'!$D$7:$D$300,$B17,'Car 10 - 01352'!$E$7:$E$300,"") -> 1 | N17: =SUM(D17:M17) -> 5
A18: ED COATED DOOR FRAME- FRT LH-BF243085 | B18: 52BF0689 | C18: ضمن: زجاج باب أمامي شمال + فريم كامل + جوانات باب + لوك + فبرة زجاج | D18: =SUMIF('Car 1 - 00569'!$D$7:$D$300,$B18,'Car 1 - 00569'!$E$7:$E$300)+COUNTIFS('Car 1 - 00569'!$D$7:$D$300,$B18,'Car 1 - 00569'!$E$7:$E$300,"") -> 0 | E18: =SUMIF('Car 2 - 01124'!$D$7:$D$300,$B18,'Car 2 - 01124'!$E$7:$E$300)+COUNTIFS('Car 2 - 01124'!$D$7:$D$300,$B18,'Car 2 - 01124'!$E$7:$E$300,"") -> 0 | F18: =SUMIF('Car 3 - 00133'!$D$7:$D$300,$B18,'Car 3 - 00133'!$E$7:$E$300)+COUNTIFS('Car 3 - 00133'!$D$7:$D$300,$B18,'Car 3 - 00133'!$E$7:$E$300,"") -> 1 | G18: =SUMIF('Car 4 - 00679'!$D$7:$D$300,$B18,'Car 4 - 00679'!$E$7:$E$300)+COUNTIFS('Car 4 - 00679'!$D$7:$D$300,$B18,'Car 4 - 00679'!$E$7:$E$300,"") -> 0 | H18: =SUMIF('Car 5 - 00557'!$D$7:$D$300,$B18,'Car 5 - 00557'!$E$7:$E$300)+COUNTIFS('Car 5 - 00557'!$D$7:$D$300,$B18,'Car 5 - 00557'!$E$7:$E$300,"") -> 1 | I18: =SUMIF('Car 6 - 00663'!$D$7:$D$300,$B18,'Car 6 - 00663'!$E$7:$E$300)+COUNTIFS('Car 6 - 00663'!$D$7:$D$300,$B18,'Car 6 - 00663'!$E$7:$E$300,"") -> 0 | J18: =SUMIF('Car 7 - 00680'!$D$7:$D$300,$B18,'Car 7 - 00680'!$E$7:$E$300)+COUNTIFS('Car 7 - 00680'!$D$7:$D$300,$B18,'Car 7 - 00680'!$E$7:$E$300,"") -> 1 | K18: =SUMIF('Car 8 - 00523'!$D$7:$D$300,$B18,'Car 8 - 00523'!$E$7:$E$300)+COUNTIFS('Car 8 - 00523'!$D$7:$D$300,$B18,'Car 8 - 00523'!$E$7:$E$300,"") -> 0 | L18: =SUMIF('Car 9 - 00097'!$D$7:$D$300,$B18,'Car 9 - 00097'!$E$7:$E$300)+COUNTIFS('Car 9 - 00097'!$D$7:$D$300,$B18,'Car 9 - 00097'!$E$7:$E$300,"") -> 1 | M18: =SUMIF('Car 10 - 01352'!$D$7:$D$300,$B18,'Car 10 - 01352'!$E$7:$E$300)+COUNTIFS('Car 10 - 01352'!$D$7:$D$300,$B18,'Car 10 - 01352'!$E$7:$E$300,"") -> 0 | N18: =SUM(D18:M18) -> 4
A19: ASSLY CHANNEL QTR GLS MTG LH PAINT-BLACK | B19: 56BF3R22 | C19: ضمن: زجاج باب أمامي شمال + فريم كامل + جوانات باب + لوك + فبرة زجاج | D19: =SUMIF('Car 1 - 00569'!$D$7:$D$300,$B19,'Car 1 - 00569'!$E$7:$E$300)+COUNTIFS('Car 1 - 00569'!$D$7:$D$300,$B19,'Car 1 - 00569'!$E$7:$E$300,"") -> 0 | E19: =SUMIF('Car 2 - 01124'!$D$7:$D$300,$B19,'Car 2 - 01124'!$E$7:$E$300)+COUNTIFS('Car 2 - 01124'!$D$7:$D$300,$B19,'Car 2 - 01124'!$E$7:$E$300,"") -> 0 | F19: =SUMIF('Car 3 - 00133'!$D$7:$D$300,$B19,'Car 3 - 00133'!$E$7:$E$300)+COUNTIFS('Car 3 - 00133'!$D$7:$D$300,$B19,'Car 3 - 00133'!$E$7:$E$300,"") -> 1 | G19: =SUMIF('Car 4 - 00679'!$D$7:$D$300,$B19,'Car 4 - 00679'!$E$7:$E$300)+COUNTIFS('Car 4 - 00679'!$D$7:$D$300,$B19,'Car 4 - 00679'!$E$7:$E$300,"") -> 0 | H19: =SUMIF('Car 5 - 00557'!$D$7:$D$300,$B19,'Car 5 - 00557'!$E$7:$E$300)+COUNTIFS('Car 5 - 00557'!$D$7:$D$300,$B19,'Car 5 - 00557'!$E$7:$E$300,"") -> 1 | I19: =SUMIF('Car 6 - 00663'!$D$7:$D$300,$B19,'Car 6 - 00663'!$E$7:$E$300)+COUNTIFS('Car 6 - 00663'!$D$7:$D$300,$B19,'Car 6 - 00663'!$E$7:$E$300,"") -> 0 | J19: =SUMIF('Car 7 - 00680'!$D$7:$D$300,$B19,'Car 7 - 00680'!$E$7:$E$300)+COUNTIFS('Car 7 - 00680'!$D$7:$D$300,$B19,'Car 7 - 00680'!$E$7:$E$300,"") -> 1 | K19: =SUMIF('Car 8 - 00523'!$D$7:$D$300,$B19,'Car 8 - 00523'!$E$7:$E$300)+COUNTIFS('Car 8 - 00523'!$D$7:$D$300,$B19,'Car 8 - 00523'!$E$7:$E$300,"") -> 0 | L19: =SUMIF('Car 9 - 00097'!$D$7:$D$300,$B19,'Car 9 - 00097'!$E$7:$E$300)+COUNTIFS('Car 9 - 00097'!$D$7:$D$300,$B19,'Car 9 - 00097'!$E$7:$E$300,"") -> 1 | M19: =SUMIF('Car 10 - 01352'!$D$7:$D$300,$B19,'Car 10 - 01352'!$E$7:$E$300)+COUNTIFS('Car 10 - 01352'!$D$7:$D$300,$B19,'Car 10 - 01352'!$E$7:$E$300,"") -> 0 | N19: =SUM(D19:M19) -> 4
A20: LAMP (LIGHT) ASSEMBLY - CABIN | B20: AL201039 | C20: فانوس ماتور | D20: =SUMIF('Car 1 - 00569'!$D$7:$D$300,$B20,'Car 1 - 00569'!$E$7:$E$300)+COUNTIFS('Car 1 - 00569'!$D$7:$D$300,$B20,'Car 1 - 00569'!$E$7:$E$300,"") -> 0 | E20: =SUMIF('Car 2 - 01124'!$D$7:$D$300,$B20,'Car 2 - 01124'!$E$7:$E$300)+COUNTIFS('Car 2 - 01124'!$D$7:$D$300,$B20,'Car 2 - 01124'!$E$7:$E$300,"") -> 1 | F20: =SUMIF('Car 3 - 00133'!$D$7:$D$300,$B20,'Car 3 - 00133'!$E$7:$E$300)+COUNTIFS('Car 3 - 00133'!$D$7:$D$300,$B20,'Car 3 - 00133'!$E$7:$E$300,"") -> 0 | G20: =SUMIF('Car 4 - 00679'!$D$7:$D$300,$B20,'Car 4 - 00679'!$E$7:$E$300)+COUNTIFS('Car 4 - 00679'!$D$7:$D$300,$B20,'Car 4 - 00679'!$E$7:$E$300,"") -> 0 | H20: =SUMIF('Car 5 - 00557'!$D$7:$D$300,$B20,'Car 5 - 00557'!$E$7:$E$300)+COUNTIFS('Car 5 - 00557'!$D$7:$D$300,$B20,'Car 5 - 00557'!$E$7:$E$300,"") -> 0 | I20: =SUMIF('Car 6 - 00663'!$D$7:$D$300,$B20,'Car 6 - 00663'!$E$7:$E$300)+COUNTIFS('Car 6 - 00663'!$D$7:$D$300,$B20,'Car 6 - 00663'!$E$7:$E$300,"") -> 0 | J20: =SUMIF('Car 7 - 00680'!$D$7:$D$300,$B20,'Car 7 - 00680'!$E$7:$E$300)+COUNTIFS('Car 7 - 00680'!$D$7:$D$300,$B20,'Car 7 - 00680'!$E$7:$E$300,"") -> 0 | K20: =SUMIF('Car 8 - 00523'!$D$7:$D$300,$B20,'Car 8 - 00523'!$E$7:$E$300)+COUNTIFS('Car 8 - 00523'!$D$7:$D$300,$B20,'Car 8 - 00523'!$E$7:$E$300,"") -> 0 | L20: =SUMIF('Car 9 - 00097'!$D$7:$D$300,$B20,'Car 9 - 00097'!$E$7:$E$300)+COUNTIFS('Car 9 - 00097'!$D$7:$D$300,$B20,'Car 9 - 00097'!$E$7:$E$300,"") -> 0 | M20: =SUMIF('Car 10 - 01352'!$D$7:$D$300,$B20,'Car 10 - 01352'!$E$7:$E$300)+COUNTIFS('Car 10 - 01352'!$D$7:$D$300,$B20,'Car 10 - 01352'!$E$7:$E$300,"") -> 0 | N20: =SUM(D20:M20) -> 1
A21: CHARGER MOBILE | B21: AL201100 | C21: ولاعه | D21: =SUMIF('Car 1 - 00569'!$D$7:$D$300,$B21,'Car 1 - 00569'!$E$7:$E$300)+COUNTIFS('Car 1 - 00569'!$D$7:$D$300,$B21,'Car 1 - 00569'!$E$7:$E$300,"") -> 0 | E21: =SUMIF('Car 2 - 01124'!$D$7:$D$300,$B21,'Car 2 - 01124'!$E$7:$E$300)+COUNTIFS('Car 2 - 01124'!$D$7:$D$300,$B21,'Car 2 - 01124'!$E$7:$E$300,"") -> 1 | F21: =SUMIF('Car 3 - 00133'!$D$7:$D$300,$B21,'Car 3 - 00133'!$E$7:$E$300)+COUNTIFS('Car 3 - 00133'!$D$7:$D$300,$B21,'Car 3 - 00133'!$E$7:$E$300,"") -> 0 | G21: =SUMIF('Car 4 - 00679'!$D$7:$D$300,$B21,'Car 4 - 00679'!$E$7:$E$300)+COUNTIFS('Car 4 - 00679'!$D$7:$D$300,$B21,'Car 4 - 00679'!$E$7:$E$300,"") -> 0 | H21: =SUMIF('Car 5 - 00557'!$D$7:$D$300,$B21,'Car 5 - 00557'!$E$7:$E$300)+COUNTIFS('Car 5 - 00557'!$D$7:$D$300,$B21,'Car 5 - 00557'!$E$7:$E$300,"") -> 0 | I21: =SUMIF('Car 6 - 00663'!$D$7:$D$300,$B21,'Car 6 - 00663'!$E$7:$E$300)+COUNTIFS('Car 6 - 00663'!$D$7:$D$300,$B21,'Car 6 - 00663'!$E$7:$E$300,"") -> 0 | J21: =SUMIF('Car 7 - 00680'!$D$7:$D$300,$B21,'Car 7 - 00680'!$E$7:$E$300)+COUNTIFS('Car 7 - 00680'!$D$7:$D$300,$B21,'Car 7 - 00680'!$E$7:$E$300,"") -> 0 | K21: =SUMIF('Car 8 - 00523'!$D$7:$D$300,$B21,'Car 8 - 00523'!$E$7:$E$300)+COUNTIFS('Car 8 - 00523'!$D$7:$D$300,$B21,'Car 8 - 00523'!$E$7:$E$300,"") -> 0 | L21: =SUMIF('Car 9 - 00097'!$D$7:$D$300,$B21,'Car 9 - 00097'!$E$7:$E$300)+COUNTIFS('Car 9 - 00097'!$D$7:$D$300,$B21,'Car 9 - 00097'!$E$7:$E$300,"") -> 0 | M21: =SUMIF('Car 10 - 01352'!$D$7:$D$300,$B21,'Car 10 - 01352'!$E$7:$E$300)+COUNTIFS('Car 10 - 01352'!$D$7:$D$300,$B21,'Car 10 - 01352'!$E$7:$E$300,"") -> 1 | N21: =SUM(D21:M21) -> 2
A22: BRACKET RR ENG SIDE 200CC | B22: BF113435 | C22: براكيت ماتور | D22: =SUMIF('Car 1 - 00569'!$D$7:$D$300,$B22,'Car 1 - 00569'!$E$7:$E$300)+COUNTIFS('Car 1 - 00569'!$D$7:$D$300,$B22,'Car 1 - 00569'!$E$7:$E$300,"") -> 0 | E22: =SUMIF('Car 2 - 01124'!$D$7:$D$300,$B22,'Car 2 - 01124'!$E$7:$E$300)+COUNTIFS('Car 2 - 01124'!$D$7:$D$300,$B22,'Car 2 - 01124'!$E$7:$E$300,"") -> 0 | F22: =SUMIF('Car 3 - 00133'!$D$7:$D$300,$B22,'Car 3 - 00133'!$E$7:$E$300)+COUNTIFS('Car 3 - 00133'!$D$7:$D$300,$B22,'Car 3 - 00133'!$E$7:$E$300,"") -> 0 | G22: =SUMIF('Car 4 - 00679'!$D$7:$D$300,$B22,'Car 4 - 00679'!$E$7:$E$300)+COUNTIFS('Car 4 - 00679'!$D$7:$D$300,$B22,'Car 4 - 00679'!$E$7:$E$300,"") -> 0 | H22: =SUMIF('Car 5 - 00557'!$D$7:$D$300,$B22,'Car 5 - 00557'!$E$7:$E$300)+COUNTIFS('Car 5 - 00557'!$D$7:$D$300,$B22,'Car 5 - 00557'!$E$7:$E$300,"") -> 1 | I22: =SUMIF('Car 6 - 00663'!$D$7:$D$300,$B22,'Car 6 - 00663'!$E$7:$E$300)+COUNTIFS('Car 6 - 00663'!$D$7:$D$300,$B22,'Car 6 - 00663'!$E$7:$E$300,"") -> 0 | J22: =SUMIF('Car 7 - 00680'!$D$7:$D$300,$B22,'Car 7 - 00680'!$E$7:$E$300)+COUNTIFS('Car 7 - 00680'!$D$7:$D$300,$B22,'Car 7 - 00680'!$E$7:$E$300,"") -> 0 | K22: =SUMIF('Car 8 - 00523'!$D$7:$D$300,$B22,'Car 8 - 00523'!$E$7:$E$300)+COUNTIFS('Car 8 - 00523'!$D$7:$D$300,$B22,'Car 8 - 00523'!$E$7:$E$300,"") -> 0 | L22: =SUMIF('Car 9 - 00097'!$D$7:$D$300,$B22,'Car 9 - 00097'!$E$7:$E$300)+COUNTIFS('Car 9 - 00097'!$D$7:$D$300,$B22,'Car 9 - 00097'!$E$7:$E$300,"") -> 1 | M22: =SUMIF('Car 10 - 01352'!$D$7:$D$300,$B22,'Car 10 - 01352'!$E$7:$E$300)+COUNTIFS('Car 10 - 01352'!$D$7:$D$300,$B22,'Car 10 - 01352'!$E$7:$E$300,"") -> 0 | N22: =SUM(D22:M22) -> 2
A23: ISOLATOR ASSEMBLY FRONT | B23: BF113461 | C23: ضمن: براكيت ماتور | D23: =SUMIF('Car 1 - 00569'!$D$7:$D$300,$B23,'Car 1 - 00569'!$E$7:$E$300)+COUNTIFS('Car 1 - 00569'!$D$7:$D$300,$B23,'Car 1 - 00569'!$E$7:$E$300,"") -> 0 | E23: =SUMIF('Car 2 - 01124'!$D$7:$D$300,$B23,'Car 2 - 01124'!$E$7:$E$300)+COUNTIFS('Car 2 - 01124'!$D$7:$D$300,$B23,'Car 2 - 01124'!$E$7:$E$300,"") -> 0 | F23: =SUMIF('Car 3 - 00133'!$D$7:$D$300,$B23,'Car 3 - 00133'!$E$7:$E$300)+COUNTIFS('Car 3 - 00133'!$D$7:$D$300,$B23,'Car 3 - 00133'!$E$7:$E$300,"") -> 0 | G23: =SUMIF('Car 4 - 00679'!$D$7:$D$300,$B23,'Car 4 - 00679'!$E$7:$E$300)+COUNTIFS('Car 4 - 00679'!$D$7:$D$300,$B23,'Car 4 - 00679'!$E$7:$E$300,"") -> 0 | H23: =SUMIF('Car 5 - 00557'!$D$7:$D$300,$B23,'Car 5 - 00557'!$E$7:$E$300)+COUNTIFS('Car 5 - 00557'!$D$7:$D$300,$B23,'Car 5 - 00557'!$E$7:$E$300,"") -> 1 | I23: =SUMIF('Car 6 - 00663'!$D$7:$D$300,$B23,'Car 6 - 00663'!$E$7:$E$300)+COUNTIFS('Car 6 - 00663'!$D$7:$D$300,$B23,'Car 6 - 00663'!$E$7:$E$300,"") -> 0 | J23: =SUMIF('Car 7 - 00680'!$D$7:$D$300,$B23,'Car 7 - 00680'!$E$7:$E$300)+COUNTIFS('Car 7 - 00680'!$D$7:$D$300,$B23,'Car 7 - 00680'!$E$7:$E$300,"") -> 0 | K23: =SUMIF('Car 8 - 00523'!$D$7:$D$300,$B23,'Car 8 - 00523'!$E$7:$E$300)+COUNTIFS('Car 8 - 00523'!$D$7:$D$300,$B23,'Car 8 - 00523'!$E$7:$E$300,"") -> 0 | L23: =SUMIF('Car 9 - 00097'!$D$7:$D$300,$B23,'Car 9 - 00097'!$E$7:$E$300)+COUNTIFS('Car 9 - 00097'!$D$7:$D$300,$B23,'Car 9 - 00097'!$E$7:$E$300,"") -> 1 | M23: =SUMIF('Car 10 - 01352'!$D$7:$D$300,$B23,'Car 10 - 01352'!$E$7:$E$300)+COUNTIFS('Car 10 - 01352'!$D$7:$D$300,$B23,'Car 10 - 01352'!$E$7:$E$300,"") -> 0 | N23: =SUM(D23:M23) -> 2
A24: ASSEMBLY ARM CONTROL LOWER RH | B24: BF121112 | C24: مقص امامي يمين | D24: =SUMIF('Car 1 - 00569'!$D$7:$D$300,$B24,'Car 1 - 00569'!$E$7:$E$300)+COUNTIFS('Car 1 - 00569'!$D$7:$D$300,$B24,'Car 1 - 00569'!$E$7:$E$300,"") -> 0 | E24: =SUMIF('Car 2 - 01124'!$D$7:$D$300,$B24,'Car 2 - 01124'!$E$7:$E$300)+COUNTIFS('Car 2 - 01124'!$D$7:$D$300,$B24,'Car 2 - 01124'!$E$7:$E$300,"") -> 0 | F24: =SUMIF('Car 3 - 00133'!$D$7:$D$300,$B24,'Car 3 - 00133'!$E$7:$E$300)+COUNTIFS('Car 3 - 00133'!$D$7:$D$300,$B24,'Car 3 - 00133'!$E$7:$E$300,"") -> 0 | G24: =SUMIF('Car 4 - 00679'!$D$7:$D$300,$B24,'Car 4 - 00679'!$E$7:$E$300)+COUNTIFS('Car 4 - 00679'!$D$7:$D$300,$B24,'Car 4 - 00679'!$E$7:$E$300,"") -> 0 | H24: =SUMIF('Car 5 - 00557'!$D$7:$D$300,$B24,'Car 5 - 00557'!$E$7:$E$300)+COUNTIFS('Car 5 - 00557'!$D$7:$D$300,$B24,'Car 5 - 00557'!$E$7:$E$300,"") -> 0 | I24: =SUMIF('Car 6 - 00663'!$D$7:$D$300,$B24,'Car 6 - 00663'!$E$7:$E$300)+COUNTIFS('Car 6 - 00663'!$D$7:$D$300,$B24,'Car 6 - 00663'!$E$7:$E$300,"") -> 0 | J24: =SUMIF('Car 7 - 00680'!$D$7:$D$300,$B24,'Car 7 - 00680'!$E$7:$E$300)+COUNTIFS('Car 7 - 00680'!$D$7:$D$300,$B24,'Car 7 - 00680'!$E$7:$E$300,"") -> 0 | K24: =SUMIF('Car 8 - 00523'!$D$7:$D$300,$B24,'Car 8 - 00523'!$E$7:$E$300)+COUNTIFS('Car 8 - 00523'!$D$7:$D$300,$B24,'Car 8 - 00523'!$E$7:$E$300,"") -> 0 | L24: =SUMIF('Car 9 - 00097'!$D$7:$D$300,$B24,'Car 9 - 00097'!$E$7:$E$300)+COUNTIFS('Car 9 - 00097'!$D$7:$D$300,$B24,'Car 9 - 00097'!$E$7:$E$300,"") -> 0 | M24: =SUMIF('Car 10 - 01352'!$D$7:$D$300,$B24,'Car 10 - 01352'!$E$7:$E$300)+COUNTIFS('Car 10 - 01352'!$D$7:$D$300,$B24,'Car 10 - 01352'!$E$7:$E$300,"") -> 1 | N24: =SUM(D24:M24) -> 1
A25: NUT CONICAL M 10 | B25: BF131486 | C25: صاموله عجل | D25: =SUMIF('Car 1 - 00569'!$D$7:$D$300,$B25,'Car 1 - 00569'!$E$7:$E$300)+COUNTIFS('Car 1 - 00569'!$D$7:$D$300,$B25,'Car 1 - 00569'!$E$7:$E$300,"") -> 0 | E25: =SUMIF('Car 2 - 01124'!$D$7:$D$300,$B25,'Car 2 - 01124'!$E$7:$E$300)+COUNTIFS('Car 2 - 01124'!$D$7:$D$300,$B25,'Car 2 - 01124'!$E$7:$E$300,"") -> 0 | F25: =SUMIF('Car 3 - 00133'!$D$7:$D$300,$B25,'Car 3 - 00133'!$E$7:$E$300)+COUNTIFS('Car 3 - 00133'!$D$7:$D$300,$B25,'Car 3 - 00133'!$E$7:$E$300,"") -> 6 | G25: =SUMIF('Car 4 - 00679'!$D$7:$D$300,$B25,'Car 4 - 00679'!$E$7:$E$300)+COUNTIFS('Car 4 - 00679'!$D$7:$D$300,$B25,'Car 4 - 00679'!$E$7:$E$300,"") -> 0 | H25: =SUMIF('Car 5 - 00557'!$D$7:$D$300,$B25,'Car 5 - 00557'!$E$7:$E$300)+COUNTIFS('Car 5 - 00557'!$D$7:$D$300,$B25,'Car 5 - 00557'!$E$7:$E$300,"") -> 0 | I25: =SUMIF('Car 6 - 00663'!$D$7:$D$300,$B25,'Car 6 - 00663'!$E$7:$E$300)+COUNTIFS('Car 6 - 00663'!$D$7:$D$300,$B25,'Car 6 - 00663'!$E$7:$E$300,"") -> 0 | J25: =SUMIF('Car 7 - 00680'!$D$7:$D$300,$B25,'Car 7 - 00680'!$E$7:$E$300)+COUNTIFS('Car 7 - 00680'!$D$7:$D$300,$B25,'Car 7 - 00680'!$E$7:$E$300,"") -> 6 | K25: =SUMIF('Car 8 - 00523'!$D$7:$D$300,$B25,'Car 8 - 00523'!$E$7:$E$300)+COUNTIFS('Car 8 - 00523'!$D$7:$D$300,$B25,'Car 8 - 00523'!$E$7:$E$300,"") -> 0 | L25: =SUMIF('Car 9 - 00097'!$D$7:$D$300,$B25,'Car 9 - 00097'!$E$7:$E$300)+COUNTIFS('Car 9 - 00097'!$D$7:$D$300,$B25,'Car 9 - 00097'!$E$7:$E$300,"") -> 0 | M25: =SUMIF('Car 10 - 01352'!$D$7:$D$300,$B25,'Car 10 - 01352'!$E$7:$E$300)+COUNTIFS('Car 10 - 01352'!$D$7:$D$300,$B25,'Car 10 - 01352'!$E$7:$E$300,"") -> 0 | N25: =SUM(D25:M25) -> 12
A26: HUB CAP - STEEL WHEEL | B26: BF131505 | C26: غطاء عجل | D26: =SUMIF('Car 1 - 00569'!$D$7:$D$300,$B26,'Car 1 - 00569'!$E$7:$E$300)+COUNTIFS('Car 1 - 00569'!$D$7:$D$300,$B26,'Car 1 - 00569'!$E$7:$E$300,"") -> 2 | E26: =SUMIF('Car 2 - 01124'!$D$7:$D$300,$B26,'Car 2 - 01124'!$E$7:$E$300)+COUNTIFS('Car 2 - 01124'!$D$7:$D$300,$B26,'Car 2 - 01124'!$E$7:$E$300,"") -> 1 | F26: =SUMIF('Car 3 - 00133'!$D$7:$D$300,$B26,'Car 3 - 00133'!$E$7:$E$300)+COUNTIFS('Car 3 - 00133'!$D$7:$D$300,$B26,'Car 3 - 00133'!$E$7:$E$300,"") -> 0 | G26: =SUMIF('Car 4 - 00679'!$D$7:$D$300,$B26,'Car 4 - 00679'!$E$7:$E$300)+COUNTIFS('Car 4 - 00679'!$D$7:$D$300,$B26,'Car 4 - 00679'!$E$7:$E$300,"") -> 0 | H26: =SUMIF('Car 5 - 00557'!$D$7:$D$300,$B26,'Car 5 - 00557'!$E$7:$E$300)+COUNTIFS('Car 5 - 00557'!$D$7:$D$300,$B26,'Car 5 - 00557'!$E$7:$E$300,"") -> 4 | I26: =SUMIF('Car 6 - 00663'!$D$7:$D$300,$B26,'Car 6 - 00663'!$E$7:$E$300)+COUNTIFS('Car 6 - 00663'!$D$7:$D$300,$B26,'Car 6 - 00663'!$E$7:$E$300,"") -> 0 | J26: =SUMIF('Car 7 - 00680'!$D$7:$D$300,$B26,'Car 7 - 00680'!$E$7:$E$300)+COUNTIFS('Car 7 - 00680'!$D$7:$D$300,$B26,'Car 7 - 00680'!$E$7:$E$300,"") -> 0 | K26: =SUMIF('Car 8 - 00523'!$D$7:$D$300,$B26,'Car 8 - 00523'!$E$7:$E$300)+COUNTIFS('Car 8 - 00523'!$D$7:$D$300,$B26,'Car 8 - 00523'!$E$7:$E$300,"") -> 0 | L26: =SUMIF('Car 9 - 00097'!$D$7:$D$300,$B26,'Car 9 - 00097'!$E$7:$E$300)+COUNTIFS('Car 9 - 00097'!$D$7:$D$300,$B26,'Car 9 - 00097'!$E$7:$E$300,"") -> 0 | M26: =SUMIF('Car 10 - 01352'!$D$7:$D$300,$B26,'Car 10 - 01352'!$E$7:$E$300)+COUNTIFS('Car 10 - 01352'!$D$7:$D$300,$B26,'Car 10 - 01352'!$E$7:$E$300,"") -> 0 | N26: =SUM(D26:M26) -> 7
A27: CABLE GEAR BLACK | B27: BF161243 | C27: كابل غيار اسود | D27: =SUMIF('Car 1 - 00569'!$D$7:$D$300,$B27,'Car 1 - 00569'!$E$7:$E$300)+COUNTIFS('Car 1 - 00569'!$D$7:$D$300,$B27,'Car 1 - 00569'!$E$7:$E$300,"") -> 0 | E27: =SUMIF('Car 2 - 01124'!$D$7:$D$300,$B27,'Car 2 - 01124'!$E$7:$E$300)+COUNTIFS('Car 2 - 01124'!$D$7:$D$300,$B27,'Car 2 - 01124'!$E$7:$E$300,"") -> 0 | F27: =SUMIF('Car 3 - 00133'!$D$7:$D$300,$B27,'Car 3 - 00133'!$E$7:$E$300)+COUNTIFS('Car 3 - 00133'!$D$7:$D$300,$B27,'Car 3 - 00133'!$E$7:$E$300,"") -> 1 | G27: =SUMIF('Car 4 - 00679'!$D$7:$D$300,$B27,'Car 4 - 00679'!$E$7:$E$300)+COUNTIFS('Car 4 - 00679'!$D$7:$D$300,$B27,'Car 4 - 00679'!$E$7:$E$300,"") -> 0 | H27: =SUMIF('Car 5 - 00557'!$D$7:$D$300,$B27,'Car 5 - 00557'!$E$7:$E$300)+COUNTIFS('Car 5 - 00557'!$D$7:$D$300,$B27,'Car 5 - 00557'!$E$7:$E$300,"") -> 0 | I27: =SUMIF('Car 6 - 00663'!$D$7:$D$300,$B27,'Car 6 - 00663'!$E$7:$E$300)+COUNTIFS('Car 6 - 00663'!$D$7:$D$300,$B27,'Car 6 - 00663'!$E$7:$E$300,"") -> 0 | J27: =SUMIF('Car 7 - 00680'!$D$7:$D$300,$B27,'Car 7 - 00680'!$E$7:$E$300)+COUNTIFS('Car 7 - 00680'!$D$7:$D$300,$B27,'Car 7 - 00680'!$E$7:$E$300,"") -> 0 | K27: =SUMIF('Car 8 - 00523'!$D$7:$D$300,$B27,'Car 8 - 00523'!$E$7:$E$300)+COUNTIFS('Car 8 - 00523'!$D$7:$D$300,$B27,'Car 8 - 00523'!$E$7:$E$300,"") -> 0 | L27: =SUMIF('Car 9 - 00097'!$D$7:$D$300,$B27,'Car 9 - 00097'!$E$7:$E$300)+COUNTIFS('Car 9 - 00097'!$D$7:$D$300,$B27,'Car 9 - 00097'!$E$7:$E$300,"") -> 0 | M27: =SUMIF('Car 10 - 01352'!$D$7:$D$300,$B27,'Car 10 - 01352'!$E$7:$E$300)+COUNTIFS('Car 10 - 01352'!$D$7:$D$300,$B27,'Car 10 - 01352'!$E$7:$E$300,"") -> 0 | N27: =SUM(D27:M27) -> 1
... A107: SCREW TAPING PAN CROS- ST3.5XL5.5 | B107: LBR00001 | C107: ضمن: قفل زجاج باب أمامي شمال | D107: =SUMIF('Car 1 - 00569'!$D$7:$D$300,$B107,'Car 1 - 00569'!$E$7:$E$300)+COUNTIFS('Car 1 - 00569'!$D$7:$D$300,$B107,'Car 1 - 00569'!$E$7:$E$300,"") -> 0 | E107: =SUMIF('Car 2 - 01124'!$D$7:$D$300,$B107,'Car 2 - 01124'!$E$7:$E$300)+COUNTIFS('Car 2 - 01124'!$D$7:$D$300,$B107,'Car 2 - 01124'!$E$7:$E$300,"") -> 0 | F107: =SUMIF('Car 3 - 00133'!$D$7:$D$300,$B107,'Car 3 - 00133'!$E$7:$E$300)+COUNTIFS('Car 3 - 00133'!$D$7:$D$300,$B107,'Car 3 - 00133'!$E$7:$E$300,"") -> 0 | G107: =SUMIF('Car 4 - 00679'!$D$7:$D$300,$B107,'Car 4 - 00679'!$E$7:$E$300)+COUNTIFS('Car 4 - 00679'!$D$7:$D$300,$B107,'Car 4 - 00679'!$E$7:$E$300,"") -> 0 | H107: =SUMIF('Car 5 - 00557'!$D$7:$D$300,$B107,'Car 5 - 00557'!$E$7:$E$300)+COUNTIFS('Car 5 - 00557'!$D$7:$D$300,$B107,'Car 5 - 00557'!$E$7:$E$300,"") -> 0 | I107: =SUMIF('Car 6 - 00663'!$D$7:$D$300,$B107,'Car 6 - 00663'!$E$7:$E$300)+COUNTIFS('Car 6 - 00663'!$D$7:$D$300,$B107,'Car 6 - 00663'!$E$7:$E$300,"") -> 0 | J107: =SUMIF('Car 7 - 00680'!$D$7:$D$300,$B107,'Car 7 - 00680'!$E$7:$E$300)+COUNTIFS('Car 7 - 00680'!$D$7:$D$300,$B107,'Car 7 - 00680'!$E$7:$E$300,"") -> 0 | K107: =SUMIF('Car 8 - 00523'!$D$7:$D$300,$B107,'Car 8 - 00523'!$E$7:$E$300)+COUNTIFS('Car 8 - 00523'!$D$7:$D$300,$B107,'Car 8 - 00523'!$E$7:$E$300,"") -> 8 | L107: =SUMIF('Car 9 - 00097'!$D$7:$D$300,$B107,'Car 9 - 00097'!$E$7:$E$300)+COUNTIFS('Car 9 - 00097'!$D$7:$D$300,$B107,'Car 9 - 00097'!$E$7:$E$300,"") -> 0 | M107: =SUMIF('Car 10 - 01352'!$D$7:$D$300,$B107,'Car 10 - 01352'!$E$7:$E$300)+COUNTIFS('Car 10 - 01352'!$D$7:$D$300,$B107,'Car 10 - 01352'!$E$7:$E$300,"") -> 0 | N107: =SUM(D107:M107) -> 8
A108: Total Parts With Part No. | D108: =SUM(D16:D107) -> 17 | E108: =SUM(E16:E107) -> 22 | F108: =SUM(F16:F107) -> 52 | G108: =SUM(G16:G107) -> 15 | H108: =SUM(H16:H107) -> 78 | I108: =SUM(I16:I107) -> 2 | J108: =SUM(J16:J107) -> 58 | K108: =SUM(K16:K107) -> 21 | ... N108: =SUM(N16:N107) -> 369
A110: Parts Without a Part No. (count = quantity listed in each car)
A111: Part (Arabic) | B111: Part No. | C111: Note | D111: Car 1 | E111: Car 2 | F111: Car 3 | G111: Car 4 | H111: Car 5 | I111: Car 6 | J111: Car 7 | K111: Car 8 | L111: Car 9 | M111: Car 10 | N111: Total
A112: حساس كلاكس | B112: No Part No. | D112: =0 -> 0 | E112: =IF(LEN(TRIM('Car 2 - 01124'!B14))>0,IF(ISNUMBER('Car 2 - 01124'!E14),'Car 2 - 01124'!E14,1),0) -> 1 | F112: =0 -> 0 | G112: =0 -> 0 | H112: =0 -> 0 | I112: =0 -> 0 | J112: =0 -> 0 | K112: =0 -> 0 | L112: =0 -> 0 | M112: =IF(LEN(TRIM('Car 10 - 01352'!B19))>0,IF(ISNUMBER('Car 10 - 01352'!E19),'Car 10 - 01352'!E19,1),0) -> 1 | N112: =SUM(D112:M112) -> 2
A113: فبرة مثلث خلفي يمين | B113: No Part No. | D113: =0 -> 0 | E113: =IF(LEN(TRIM('Car 2 - 01124'!B16))>0,IF(ISNUMBER('Car 2 - 01124'!E16),'Car 2 - 01124'!E16,1),0) -> 1 | F113: =0 -> 0 | G113: =0 -> 0 | H113: =0 -> 0 | I113: =0 -> 0 | J113: =0 -> 0 | K113: =0 -> 0 | L113: =0 -> 0 | M113: =0 -> 0 | N113: =SUM(D113:M113) -> 1
A114: فبرة مثلث يمين وشمال | B114: No Part No. | D114: =0 -> 0 | E114: =0 -> 0 | F114: =0 -> 0 | G114: =0 -> 0 | H114: =0 -> 0 | I114: =0 -> 0 | J114: =0 -> 0 | K114: =0 -> 0 | L114: =0 -> 0 | M114: =IF(LEN(TRIM('Car 10 - 01352'!B29))>0,IF(ISNUMBER('Car 10 - 01352'!E29),'Car 10 - 01352'!E29,1),0) -> 1 | N114: =SUM(D114:M114) -> 1
A115: عتبة يمين | B115: No Part No. | D115: =0 -> 0 | E115: =0 -> 0 | F115: =0 -> 0 | G115: =0 -> 0 | H115: =IF(LEN(TRIM('Car 5 - 00557'!B11))>0,IF(ISNUMBER('Car 5 - 00557'!E11),'Car 5 - 00557'!E11,1),0) -> 1 | I115: =0 -> 0 | J115: =0 -> 0 | K115: =0 -> 0 | L115: =0 -> 0 | M115: =IF(LEN(TRIM('Car 10 - 01352'!B16))>0,IF(ISNUMBER('Car 10 - 01352'!E16),'Car 10 - 01352'!E16,1),0) -> 1 | N115: =SUM(D115:M115) -> 2
A116: عتبة شمال | B116: No Part No. | D116: =0 -> 0 | E116: =IF(LEN(TRIM('Car 2 - 01124'!B11))>0,IF(ISNUMBER('Car 2 - 01124'!E11),'Car 2 - 01124'!E11,1),0) -> 1 | F116: =0 -> 0 | G116: =0 -> 0 | H116: =IF(LEN(TRIM('Car 5 - 00557'!B12))>0,IF(ISNUMBER('Car 5 - 00557'!E12),'Car 5 - 00557'!E12,1),0) -> 1 | I116: =0 -> 0 | J116: =0 -> 0 | K116: =0 -> 0 | L116: =0 -> 0 | M116: =IF(LEN(TRIM('Car 10 - 01352'!B17))>0,IF(ISNUMBER('Car 10 - 01352'!E17),'Car 10 - 01352'!E17,1),0) -> 1 | N116: =SUM(D116:M116) -> 3
A117: شبكة علوية | B117: No Part No. | C117: Under repair | D117: =0 -> 0 | E117: =IF(LEN(TRIM('Car 2 - 01124'!B36))>0,IF(ISNUMBER('Car 2 - 01124'!E36),'Car 2 - 01124'!E36,1),0) -> 1 | F117: =0 -> 0 | G117: =0 -> 0 | H117: =IF(LEN(TRIM('Car 5 - 00557'!B61))>0,IF(ISNUMBER('Car 5 - 00557'!E61),'Car 5 - 00557'!E61,1),0) -> 1 | I117: =0 -> 0 | J117: =0 -> 0 | K117: =0 -> 0 | L117: =IF(LEN(TRIM('Car 9 - 00097'!B68))>0,IF(ISNUMBER('Car 9 - 00097'!E68),'Car 9 - 00097'!E68,1),0) -> 1 | M117: =IF(LEN(TRIM('Car 10 - 01352'!B41))>0,IF(ISNUMBER('Car 10 - 01352'!E41),'Car 10 - 01352'!E41,1),0) -> 1 | N117: =SUM(D117:M117) -> 4
A118: حامل نمرة | B118: No Part No. | D118: =0 -> 0 | E118: =0 -> 0 | F118: =0 -> 0 | G118: =IF(LEN(TRIM('Car 4 - 00679'!B22))>0,IF(ISNUMBER('Car 4 - 00679'!E22),'Car 4 - 00679'!E22,1),0) -> 1 | H118: =0 -> 0 | I118: =0 -> 0 | J118: =0 -> 0 | K118: =0 -> 0 | L118: =0 -> 0 | M118: =IF(LEN(TRIM('Car 10 - 01352'!B15))>0,IF(ISNUMBER('Car 10 - 01352'!E15),'Car 10 - 01352'!E15,1),0) -> 1 | N118: =SUM(D118:M118) -> 2
A119: كاتم صوت فلتر الهواء (فبرة) | B119: No Part No. | C119: Broken | D119: =0 -> 0 | E119: =IF(LEN(TRIM('Car 2 - 01124'!B31))>0,IF(ISNUMBER('Car 2 - 01124'!E31),'Car 2 - 01124'!E31,1),0) -> 1 | F119: =0 -> 0 | G119: =0 -> 0 | H119: =0 -> 0 | I119: =0 -> 0 | J119: =0 -> 0 | K119: =0 -> 0 | L119: =IF(LEN(TRIM('Car 9 - 00097'!B39))>0,IF(ISNUMBER('Car 9 - 00097'!E39),'Car 9 - 00097'!E39,1),0) -> 1 | M119: =0 -> 0 | N119: =SUM(D119:M119) -> 2
A120: كالون باب أمامي يمين | B120: No Part No. | D120: =IF(LEN(TRIM('Car 1 - 00569'!B9))>0,IF(ISNUMBER('Car 1 - 00569'!E9),'Car 1 - 00569'!E9,1),0) -> 1 | E120: =0 -> 0 | F120: =IF(LEN(TRIM('Car 3 - 00133'!B27))>0,IF(ISNUMBER('Car 3 - 00133'!E27),'Car 3 - 00133'!E27,1),0) -> 1 | G120: =IF(LEN(TRIM('Car 4 - 00679'!B11))>0,IF(ISNUMBER('Car 4 - 00679'!E11),'Car 4 - 00679'!E11,1),0) -> 1 | H120: =0 -> 0 | I120: =0 -> 0 | J120: =IF(LEN(TRIM('Car 7 - 00680'!B24))>0,IF(ISNUMBER('Car 7 - 00680'!E24),'Car 7 - 00680'!E24,1),0) -> 1 | K120: =0 -> 0 | L120: =IF(LEN(TRIM('Car 9 - 00097'!B12))>0,IF(ISNUMBER('Car 9 - 00097'!E12),'Car 9 - 00097'!E12,1),0) -> 1 | M120: =0 -> 0 | N120: =SUM(D120:M120) -> 5
A121: كالون باب أمامي شمال | B121: No Part No. | D121: =0 -> 0 | E121: =0 -> 0 | F121: =0 -> 0 | G121: =0 -> 0 | H121: =IF(LEN(TRIM('Car 5 - 00557'!B30))>0,IF(ISNUMBER('Car 5 - 00557'!E30),'Car 5 - 00557'!E30,1),0) -> 1 | I121: =0 -> 0 | J121: =0 -> 0 | K121: =0 -> 0 | L121: =0 -> 0 | M121: =0 -> 0 | N121: =SUM(D121:M121) -> 1
...

Sheet Car 1 - 00569
A1: Chassis No. | B1: MD2A68CX5TWb00569
A2: Engine No. | B2: BFXWTB23429
A3: Operating Status
A4: Date | B4: 25/10/2026
A5: Color | B5: White
A6: No. | B6: Missing Part (Arabic) | C6: Part Name | D6: Part No. | E6: Quantity
A7: 1 | B7: كابترة أمامي يمين علوية | C7: GUARD SPLASH FRONT RH UPPER | D7: BF185025 | E7: 1
A8: 2 | B8: غطاء عجل | C8: HUB CAP - STEEL WHEEL | D8: BF131505 | E8: 2
A9: 3 | B9: كالون باب أمامي يمين
A10: 4 | B10: كالون باب خلفي يمين
A11: 5 | B11: فبرة زجاج باب أمامي يمين سفليه | C11: COVER SLIDING FRT DOOR BTM RH | D11: BF243074 | E11: 1
A12: 6 | B12: فبرة درج باب أمامي يمين | C12: DOOR TRIM PANEL FRONT RH | D12: BF182403 | E12: 1
A13: 7 | B13: كلبسات فبرة زجاج | C13: CLIP | D13: BF241152 | E13: 8
A14: 8 | B14: طقم مراوح خلفي | C14: FAN ASSEMBLY REAR | D14: BF253490 | E14: 1
A15: 9 | B15: جبل باب ماتور | C15: STRING ENGINE ACC COVER STOPPER | D15: BF244009 | E15: 2
A16: 10 | B16: مروحة أمامى | C16: FAN ASSEMBLY FRONT | D16: BF253489 | E16: 1

Sheet Car 2 - 01124
A1: Chassis No. | B1: MD2A68CX5TWK01124
A2: Engine No.
A3: Operating Status | B3: Accident - at the bodywork and paint shop
A4: Date | B4: 25/10/2026
A5: Color | B5: Red
A7: No. | B7: Missing Part (Arabic) | C7: Part Name | D7: Part No. | E7: Quantity
A8: 1 | B8: فانوس أمامي يمين | C8: HEAD LAMP RH ASYM BEAM LHD 60 55W | D8: BF401136 | E8: 1
A9: 2 | B9: زجاج أمامي | C9: Broken (another glass was delivered to the factory, c/o Eng. Naseem)
A10: 3 | B10: اكصدام أمامي | C10: BUMPER FRONT | D10: BF182006 | E10: 1
A11: 4 | B11: عتبة أمامي شمال
A12: 5 | B12: طبة عتبة يمين | C12: CAP TR ARM MOUNTING RH | D12: BF185011 | E12: 1
A13: 6 | B13: ولاعه | C13: CHARGER MOBILE | D13: AL201100 | E13: 1
A14: 7 | B14: حساس كلاكس
B15: كاسيت
A16: 8 | B16: فبرة مثلث خلفي يمين
A17: 9 | B17: فانوس خلفي شمال | C17: ASSEMBLY 4WH TAIL LAMP LH 16W | D17: BF401139 | E17: 1
A18: 10 | B18: شالتة خلفي | C18: CUSHION ASSEMBLY-SEAT- REAR | D18: BF191207 | E18: 1
A19: 11 | B19: شاسيه كرسي السائق | C19: ASSEMBLY SEAT DRIVER | D19: BF191175 | E19: 1
A20: 12 | B20: فبرة كونسولة | C20: COVER MIDDLE UPPER CNG | D20: BF182588 | E20: 1
B21: فيبرة حزام خلفى يمين | C21: SEAT BELT ELR REAR COVER RH | D21: BF182624 | E21: 1
B22: فيبرة حزام خلفى شمال | C22: SEAT BELT ELR REAR COVER LH | D22: BF182625 | E22: 1
B23: طقم حزام خلفي | C23: BELT ASSEMBLY SEAT REAR | D23: BF182635 | E23: 1
A24: 13 | B24: طقم حزام أمامي | C24: BELT ASSEMBLY SEAT FRONT | D24: BF182634 | E24: 1
B25: جوان جانب خارجي | C25: GUIDE CHNL BEADING FRT FRT | D25: BF243092 | E25: 1
C26: BEADING CHANNEL L = 300 | D26: BF243113 | E26: 1
A27: 14 | C27: BEADING CHANNEL SLIDING | D27: BF243096 | E27: 1
A28: 15 | B28: فبرة زجاج باب أمامي يمين سفليه | C28: COVER SLIDING FRT DOOR BTM RH | D28: BF243074 | E28: 1
A29: 16 | B29: مرايا يمين | C29: ORVM RH | D29: BF184638 | E29: 1
A30: 17 | B30: باب خلفي يمين + فريم + زجاج + جوانة + فبرة زجاج | C30: ASSEMBLY REAR DOOR COMP RH WHITE | D30: 52BF0102 | E30: 1
A31: 18 | B31: فبرة كاتم فلتر هواء | C31: Broken
A32: 19 | B32: مرايا صالون | C32: IRVM | D32: BF184620 | E32: 1
A33: 20 | B33: فريم زجاج خلفي | C33: GLASS TAILGATE | D33: BF186029 | E33: 1
A34: 21 | B34: فانوس ماتور | C34: LAMP (LIGHT) ASSEMBLY - CABIN | D34: AL201039 | E34: 1
A35: 22 | B35: غطاء عجل | C35: HUB CAP - STEEL WHEEL | D35: BF131505 | E35: 1
A36: 23 | B36: شبكة علوية | C36: Under repair | E36: 1

Sheet Car 3 - 00133
A1: Chassis No. | B1: MD2A68CX4TWM00133
A2: Engine No. | B2: BXXWTM21238
A3: Operating Status | B3: Not running - needs ECU inspection
A4: Date | B4: 25/10/2026
A5: Color | B5: Yellow
A7: No. | B7: Missing Part (Arabic) | C7: Part Name | D7: Part No. | E7: Quantity
A8: 1 | B8: دلاية أمامي شمال | C8: MUDFLAP FRONT LH | D8: BF185072 | E8: 1
B9: زجاج باب أمامي شمال + فريم كامل + جوانات باب + لوك + فبرة زجاج | C9: FRAME DOOR FRONT LH | D9: BF243085 | E9: 1
C10: BEADING FRONT LH LOWER | D10: BF243091 | E10: 1
C11: GUIDE CHNL BEADING RR FRT | D11: BF243093 | E11: 2
C12: ED COATED DOOR FRAME- FRT LH-BF243085 | D12: 52BF0689 | E12: 1
C13: ASSLY CHANNEL QTR GLS MTG LH PAINT-BLACK | D13: 56BF3R22 | E13: 1
C14: CHANNEL GLASS DOOR FR LOWER LH | D14: BF243058 | E14: 1
C15: COVER SLIDING FRT DOOR BTM LH | D15: BF243073 | E15: 1
C16: LOCK RE60 SLIDING GLASS | D16: BF243066 | E16: 2
C17: LATCH FRONT DOOR-REAR GLASS-LH | D17: BF243102 | E17: 1
C18: LATCH FRONT DOOR-REAR GLASS-RH | D18: BF243103 | E18: 1
C19: CHANNEL FRT DOOR SLIDING TOP LH | D19: BF243057 | E19: 1
C20: CLIP | D20: BF241152 | E20: 16
C21: GLASS WINDOW FRONT FRONT LH | D21: BF243049 | E21: 1
A22: 2 | C22: GLASS WINDOW FRONT REAR LH | D22: BF243050 | E22: 1
A23: 3 | B23: صاموله عجل | C23: NUT CONICAL M 10 | D23: BF131486 | E23: 6
A24: 4 | B24: وش مفتاح إنتظار | C24: HOUSING SWITCH LHD | D24: BF182300 | E24: 1
A25: 5 | B25: فبرة درج باب أمامي يمين | C25: DOOR TRIM PANEL FRONT RH | D25: BF182403 | E25: 1
A26: 6 | B26: فبرة زجاج باب أمامي يمين سفليه | C26: COVER SLIDING FRT DOOR BTM RH | D26: BF243074 | E26: 1
A27: 7 | B27: كالون باب أمامي يمين | E27: 1
A28: 8 | B28: كالون باب خلفي يمين | E28: 1
A29: 9 | B29: فبرة سفلية باب خلفي يمين | C29: DOOR TRIM PANEL REAR RH | D29: BF182435 | E29: 1
A30: 10 | B30: فيبرة حزام خلفى يمين | C30: SEAT BELT ELR REAR COVER RH | D30: BF182624 | E30: 1
B31: فيبرة حزام خلفى شمال | C31: SEAT BELT ELR REAR COVER LH | D31: BF182625 | E31: 1
B32: طقم حزام خلفي | C32: BELT ASSEMBLY SEAT REAR | D32: BF182635 | E32: 1
B33: طقم حزام أمامي | C33: BELT ASSEMBLY SEAT FRONT | D33: BF182634 | E33: 1
A34: 11 | B34: فبرة كابترة عجل خلفي يمين أمامي | C34: GUARD SPLASH REAR RH FRONT | D34: BF185077 | E34: 1
A35: 12 | B35: جبل باب ماتور | C35: STRING ENGINE ACC COVER STOPPER | D35: BF244009 | E35: 2
A36: 13 | B36: كنترول | C36: ECU | D36: JP351439 | E36: 1
A37: 14 | B37: كابل غيار اسود | C37: CABLE GEAR BLACK | D37: BF161243 | E37: 1
A38: 15 | B38: درج باب خلفي يمين | C38: DOOR TRIM PANEL REAR RH | D38: BF182435 | E38: 1

Sheet Car 4 - 00679
A1: Chassis No. | B1: MD2A68CX1WTB00679
A2: Engine No. | B2: BFXWTB23607
A3: Operating Status | B3: Accident - at the bodywork and paint shop
A4: Date | B4: 25/10/2026
A5: Color | B5: White
A7: No. | B7: Missing Part (Arabic) | C7: Part Name | D7: Part No. | E7: Quantity
A8: 1 | B8: فانوس أمامي يمين | C8: HEAD LAMP RH ASYM BEAM LHD 60 55W | D8: BF401136 | E8: 1
A9: 2 | B9: اكصدام | C9: BUMPER FRONT | D9: BF182006 | E9: 1
A10: 3 | B10: كابترة أمامي يمين علوية | C10: GUARD SPLASH FRONT RH UPPER | D10: BF185025 | E10: 1
A11: 4 | B11: كالون باب أمامي يمين | E11: 1
A12: 5 | B12: فبرة درج باب أمامي يمين | C12: DOOR TRIM PANEL FRONT RH | D12: BF182403 | E12: 1
A13: 6 | B13: فبرة زجاج باب أمامي يمين سفليه | C13: COVER SLIDING FRT DOOR BTM RH | D13: BF243074 | E13: 1
A14: 7 | B14: طبة عتبة يمين | C14: CAP TR ARM MOUNTING RH | D14: BF185011 | E14: 1
A15: 8 | B15: باب خلفي يمين كامل + فريم + زجاج + جوانة + فبرة زجاج | C15: ASSEMBLY REAR DOOR COMP RH WHITE | D15: 52BF0102 | E15: 1
A16: 9 | B16: افيز بطارية | C16: BRACKET CLAMP BATTERY | D16: BF211543 | E16: 1
C17: ARRESTER BATTERY CLAMP ROD | D17: BF211544 | E17: 1
C18: NUT HEX FLANGED | D18: KCGD0606 | E18: 2
C19: BOLT FLANGED M6X1 | D19: KADT0612 | E19: 2
A20: 10 | B20: دلايه ماتور شمال | C20: COVER SIDE LH CNG | D20: BF182591 | E20: 1
B21: دلايه ماتور يمين | C21: COVER SIDE RH CNG | D21: BF182590 | E21: 1
A22: 11 | B22: حامل نمرة | E22: 1

Sheet Car 5 - 00557
A1: Chassis No. | B1: MD2A68CX9TWB00557
A2: Engine No. | B2: Engine dismantled
A3: Operating Status | B3: Not running
A4: Date | B4: 25/10/2026
A5: Color | B5: White
A7: No. | B7: Missing Part (Arabic) | C7: Part Name | D7: Part No. | E7: Quantity
A8: 1 | B8: فانوس أمامي يمين | C8: HEAD LAMP RH ASYM BEAM LHD 60 55W | D8: BF401136 | E8: 1
A9: 2 | B9: كابترة أمامي يمين علوية | C9: GUARD SPLASH FRONT RH UPPER | D9: BF185025 | E9: 1
A10: 3 | B10: دلاية أمامي شمال | C10: MUDFLAP FRONT LH | D10: BF185072 | E10: 1
A11: 4 | B11: عتبه يمين | D11: 1
B12: عتبه شمال | D12: 1
A13: 5 | B13: مرايه يمين | C13: ORVM RH | D13: BF184638 | E13: 1
B14: مرايه شمال | C14: ORVM LH | D14: BF184637 | E14: 1
A15: 6 | B15: غطاء عجل | C15: HUB CAP - STEEL WHEEL | D15: BF131505 | E15: 4
A16: 7 | B16: زجاج أمامي شمال + فريم + جوانة + فبرة زجاج | C16: FRAME DOOR FRONT LH | D16: BF243085 | E16: 1
C17: BEADING FRONT LH LOWER | D17: BF243091 | E17: 1
C18: GUIDE CHNL BEADING RR FRT | D18: BF243093 | E18: 2
C19: ED COATED DOOR FRAME- FRT LH-BF243085 | D19: 52BF0689 | E19: 1
C20: ASSLY CHANNEL QTR GLS MTG LH PAINT-BLACK | D20: 56BF3R22 | E20: 1
C21: CHANNEL GLASS DOOR FR LOWER LH | D21: BF243058 | E21: 1
C22: COVER SLIDING FRT DOOR BTM LH | D22: BF243073 | E22: 1
C23: LOCK RE60 SLIDING GLASS | D23: BF243066 | E23: 2
C24: LATCH FRONT DOOR-REAR GLASS-LH | D24: BF243102 | E24: 1
C25: LATCH FRONT DOOR-REAR GLASS-RH | D25: BF243103 | E25: 1
C26: CHANNEL FRT DOOR SLIDING TOP LH | D26: BF243057 | E26: 1
C27: CLIP | D27: BF241152 | E27: 16
C28: GLASS WINDOW FRONT FRONT LH | D28: BF243049 | E28: 1
C29: GLASS WINDOW FRONT REAR LH | D29: BF243050 | E29: 1
A30: 8 | B30: كالون باب أمامي شمال | E30: 1
A31: 10 | B31: مروحه امامي | C31: FAN ASSEMBLY FRONT | D31: BF253489 | E31: 1
B32: مروحه خلفي | C32: FAN ASSEMBLY REAR | D32: BF253490 | E32: 1
A33: 11 | B33: حزام خلفي | C33: BELT ASSEMBLY SEAT REAR | D33: BF182635 | E33: 1
B34: حزام أمامي | C34: BELT ASSEMBLY SEAT FRONT | D34: BF182634 | E34: 1
B35: فيبرة حزام خلفى يمين | C35: SEAT BELT ELR REAR COVER RH | D35: BF182624 | E35: 1
B36: فيبرة حزام خلفى شمال | C36: SEAT BELT ELR REAR COVER LH | D36: BF182625 | E36: 1
A37: 12 | B37: كونسولة | C37: COVER MIDDLE UPPER CNG | D37: BF182588 | E37: 1
B38: مفتاح انتظار | C38: SWITCH HAZARD WITH ILLUMINATION | D38: BF401444 | E38: 1
A39: 13 | B39: وش مفتاح إنتظار | C39: HOUSING SWITCH LHD | D39: BF182300 | E39: 1
A40: 14 | B40: كابترة خلفي يمين أمامي | C40: GUARD SPLASH REAR RH FRONT | D40: BF185077 | E40: 1
A41: 15 | B41: دلاية خلفي يمين | C41: MUDFLAP REAR RH | D41: BF185068 | E41: 1
...

Sheet Car 6 - 00663
A1: Chassis No. | B1: MD2A68CX8TWB00663
A2: Engine No. | B2: BFXWTB23627
A3: Operating Status | B3: Running
A4: Date | B4: 25/10/2026
A5: Color | B5: Blue
A7: No. | B7: Missing Part (Arabic) | C7: Part Name | D7: Part No. | E7: Quantity
A8: 1 | B8: كالون باب خلفي يمين | E8: 1
A9: 2 | B9: طبة عتبة يمين | C9: CAP TR ARM MOUNTING RH | D9: BF185011 | E9: 1
A10: 3 | B10: طبة عتبة شمال | C10: CAP TR ARM MOUNTING LH | D10: BF185010 | E10: 1

Sheet Car 7 - 00680
A1: Chassis No. | B1: MD2A68CX8TWB00680
A2: Engine No. | B2: BFXWTB23163
A3: Operating Status | B3: Not running
A4: Date | B4: 25/10/2026
A5: Color | B5: White
A7: No. | B7: Missing Part (Arabic) | C7: Part Name | D7: Part No. | E7: Quantity
A8: 1 | B8: صاموله عجل | C8: NUT CONICAL M 10 | D8: BF131486 | E8: 6
A9: 2 | B9: زجاج باب أمامي شمال + فريم كامل | C9: FRAME DOOR FRONT LH | D9: BF243085 | E9: 1
C10: BEADING FRONT LH LOWER | D10: BF243091 | E10: 1
C11: GUIDE CHNL BEADING RR FRT | D11: BF243093 | E11: 2
C12: ED COATED DOOR FRAME- FRT LH-BF243085 | D12: 52BF0689 | E12: 1
C13: ASSLY CHANNEL QTR GLS MTG LH PAINT-BLACK | D13: 56BF3R22 | E13: 1
C14: CHANNEL GLASS DOOR FR LOWER LH | D14: BF243058 | E14: 1
C15: COVER SLIDING FRT DOOR BTM LH | D15: BF243073 | E15: 1
C16: LOCK RE60 SLIDING GLASS | D16: BF243066 | E16: 2
C17: LATCH FRONT DOOR-REAR GLASS-LH | D17: BF243102 | E17: 1
C18: LATCH FRONT DOOR-REAR GLASS-RH | D18: BF243103 | E18: 1
C19: CHANNEL FRT DOOR SLIDING TOP LH | D19: BF243057 | E19: 1
C20: CLIP | D20: BF241152 | E20: 16
C21: GLASS WINDOW FRONT FRONT LH | D21: BF243049 | E21: 1
C22: GLASS WINDOW FRONT REAR LH | D22: BF243050 | E22: 1
A23: 3 | B23: مرايا شمال | C23: ORVM LH | D23: BF184637 | E23: 1
A24: 4 | B24: كالون باب أمامي يمين | E24: 1
A25: 5 | B25: فبرة درج باب أمامي يمين | C25: DOOR TRIM PANEL FRONT RH | D25: BF182403 | E25: 1
A26: 6 | B26: مروحه امامي | C26: FAN ASSEMBLY FRONT | D26: BF253489 | E26: 1
B27: مروحه خلفي | C27: FAN ASSEMBLY REAR | D27: BF253490 | E27: 1
A28: 7 | B28: كالون باب خلفي يمين | E28: 1
A29: 8 | B29: افيز بطارية | C29: BRACKET CLAMP BATTERY | D29: BF211543 | E29: 1
C30: ARRESTER BATTERY CLAMP ROD | D30: BF211544 | E30: 1
C31: NUT HEX FLANGED | D31: KCGD0606 | E31: 2
C32: BOLT FLANGED M6X1 | D32: KADT0612 | E32: 2
A33: 9 | B33: براكيت شالتة خلفي | C33: عموله | E33: 2
A34: 10 | B34: لوك زجاج باب خلفي يمين خلفي | C34: LATCH GLASS DOOR REAR RH | D34: BF243105 | E34: 1
C35: LATCH REAR DOOR-REAR GLASS-RH | D35: BF243107 | E35: 1
C36: LATCH FRONT DOOR-REAR GLASS-RH | D36: BF243103 | E36: 1
C37: LOCK RE60 SLIDING GLASS | D37: BF243066 | E37: 8

Sheet Car 8 - 00523
A1: Chassis No. | B1: MD2A68CX3TWB00523
A2: Engine No. | B2: BFXWTB2345
A3: Operating Status | B3: Running
A4: Date | B4: 25/10/2026
A5: Color | B5: White
A7: No. | B7: Missing Part (Arabic) | C7: Part Name | D7: Part No. | E7: Quantity
A8: 1 | B8: قفل زجاج باب أمامي شمال | C8: LATCH FRONT DOOR-REAR GLASS-LH | D8: BF243102 | E8: 1
C9: LATCH GLASS DOOR REAR LH | D9: BF243104 | E9: 1
C10: LATCH REAR DOOR-REAR GLASS-LH | D10: BF243106 | E10: 1
C11: LOCK RE60 SLIDING GLASS | D11: BF243066 | E11: 8
C12: SCREW TAPING PAN CROS- ST3.5XL5.5 | D12: LBR00001 | E12: 8
A13: 2 | B13: فبرة درج باب أمامي يمين | C13: DOOR TRIM PANEL FRONT RH | D13: BF182403 | E13: 1
A14: 3 | B14: كالون باب خلفي يمين | E14: 1
A15: 4 | B15: طبة عتبة يمين | C15: CAP TR ARM MOUNTING RH | D15: BF185011 | E15: 1

Sheet Car 9 - 00097
A1: Chassis No. | B1: MD2A68CX4TWM00097
A2: Engine No. | B2: BFXWTM21314
A3: Operating Status | B3: Engine is at the service center
A4: Date | B4: 25/10/2026
A5: Color | B5: White
A7: No. | B7: Missing Part (Arabic) | C7: Part Name | D7: Part No. | E7: Quantity
A8: 1 | B8: فانوس أمامي يمين | C8: HEAD LAMP RH ASYM BEAM LHD 60 55W | D8: BF401136 | E8: 1
A9: 2 | B9: كابترة أمامي يمين علوية | C9: GUARD SPLASH FRONT RH UPPER | D9: BF185025 | E9: 1
A10: 3 | B10: مرايا شمال | C10: ORVM LH | D10: BF184637 | E10: 1
B11: مرايا يمين | C11: ORVM RH | D11: BF184638 | E11: 1
A12: 4 | B12: كالون باب أمامي يمين | E12: 1
A13: 5 | B13: فبرة زجاج باب أمامي يمين سفليه | C13: COVER SLIDING FRT DOOR BTM RH | D13: BF243074 | E13: 1
A14: 6 | B14: زجاج باب أمامي شمال + فريم كامل + جوانات + فبرة زجاج | C14: FRAME DOOR FRONT LH | D14: BF243085 | E14: 1
C15: BEADING FRONT LH LOWER | D15: BF243091 | E15: 1
C16: GUIDE CHNL BEADING RR FRT | D16: BF243093 | E16: 2
C17: ED COATED DOOR FRAME- FRT LH-BF243085 | D17: 52BF0689 | E17: 1
C18: ASSLY CHANNEL QTR GLS MTG LH PAINT-BLACK | D18: 56BF3R22 | E18: 1
C19: CHANNEL GLASS DOOR FR LOWER LH | D19: BF243058 | E19: 1
C20: COVER SLIDING FRT DOOR BTM LH | D20: BF243073 | E20: 1
C21: LOCK RE60 SLIDING GLASS | D21: BF243066 | E21: 2
C22: LATCH FRONT DOOR-REAR GLASS-LH | D22: BF243102 | E22: 1
C23: LATCH FRONT DOOR-REAR GLASS-RH | D23: BF243103 | E23: 1
C24: CHANNEL FRT DOOR SLIDING TOP LH | D24: BF243057 | E24: 1
C25: CLIP | D25: BF241152 | E25: 16
C26: GLASS WINDOW FRONT FRONT LH | D26: BF243049 | E26: 1
C27: GLASS WINDOW FRONT REAR LH | D27: BF243050 | E27: 1
A28: 7 | B28: باب خلفي يمين كامل + زجاج + فريم + فبرة زجاج + جوانات | C28: ASSEMBLY REAR DOOR COMP RH WHITE | D28: 52BF0102 | E28: 1
A29: 8 | B29: حزام خلفي | C29: BELT ASSEMBLY SEAT REAR | D29: BF182635 | E29: 1
B30: حزام أمامي | C30: BELT ASSEMBLY SEAT FRONT | D30: BF182634 | E30: 1
B31: فيبرة حزام خلفى يمين | C31: SEAT BELT ELR REAR COVER RH | D31: BF182624 | E31: 1
B32: فيبرة حزام خلفى شمال | C32: SEAT BELT ELR REAR COVER LH | D32: BF182625 | E32: 1
A33: 9 | B33: مفتاح انتظار | C33: SWITCH HAZARD WITH ILLUMINATION | D33: BF401444 | E33: 1
B34: وش مفتاح إنذار | C34: HOUSING SWITCH LHD | D34: BF182300 | E34: 1
A35: 10 | B35: طبة عتبة يمين | C35: CAP TR ARM MOUNTING RH | D35: BF185011 | E35: 1
A36: 11 | B36: كابترة خلفي يمين أمامي | C36: GUARD SPLASH REAR RH FRONT | D36: BF185077 | E36: 1
A37: 12 | B37: دلايه خلفي شمال | C37: MUDFLAP REAR LH | D37: BF185069 | E37: 1
B38: دلايه خلفي يمين | C38: MUDFLAP REAR RH | D38: BF185068 | E38: 1
A39: 13 | B39: كاتم صوت فلتر الهواء
A40: 14 | B40: افيز بطارية | C40: BRACKET CLAMP BATTERY | D40: BF211543 | E40: 1
C41: ARRESTER BATTERY CLAMP ROD | D41: BF211544 | E41: 1
...

Sheet Car 10 - 01352
A1: Chassis No. | B1: MD2A68CX7TWK01352
A2: Engine No. | B2: BFXWTK20030
A3: Operating Status | B3: Accident
A4: Date | B4: 25/10/2026
A5: Color | B5: White
A7: No. | B7: Missing Part (Arabic) | C7: Part Name | D7: Part No. | E7: Quantity
A8: 1 | B8: كارتيره أمامي يمين علوية | C8: GUARD SPLASH FRONT RH UPPER | D8: BF185025 | E8: 1
B9: كارتيره أمامي يمين سفلي | C9: GUARD SPLASH FRONT RH LOWER | D9: BF185026 | E9: 1
A10: 3 | B10: فانوس أمامي يمين | C10: HEAD LAMP RH ASYM BEAM LHD 60 55W | D10: BF401136 | E10: 1
B11: فانوس أمامي شمال | C11: HEAD LAMP LH ASYM BEAM LHD 60 55W | D11: BF401135 | E11: 1
A12: 4 | B12: مساحة | C12: WIPER ASSEMBLY RE 43 LHD | D12: BF187009 | E12: 1
A13: 5 | B13: مقص امامي يمين | C13: ASSEMBLY ARM CONTROL LOWER RH | D13: BF121112 | E13: 1
A14: 6 | B14: اكصدام | C14: BUMPER FRONT | D14: BF182006 | E14: 1
B15: حامل نمرة | E15: 1
A16: 7 | B16: عتبة باب أمامي يمين | E16: 1
B17: عتبة باب أمامي شمال | E17: 1
A18: 8 | B18: ولاعه | C18: CHARGER MOBILE | D18: AL201100 | E18: 1
A19: 9 | B19: حساس كلاكس | D19: نعم | E19: 1
A20: 10 | B20: مفصلة باب أمامي يمين | C20: HINGE ASSEMBLY DOOR FRONT LH | D20: BF247026 | E20: 1 | F20: The catalog only has the code for the LEFT hinge - please review
C21: ASSEMBLY HINGE RR DOOR LH BTM | D21: BF247032 | E21: 1 | F21: The catalog only has the code for the LEFT hinge - please review
A22: 11 | B22: كالون باب امامي شمال | E22: 1
B23: طقم كونتاكت | C23: KIT SET LOCK LHD | D23: 36BF0024 | E23: 1 | F23: A right-side contact lock cylinder is available in the store and can be modified - please review. The problem is in the front-left door key lock cylinder
A24: 12 | B24: حزام خلفي | C24: BELT ASSEMBLY SEAT REAR | D24: BF182635 | E24: 1
B25: حزام أمامي | C25: BELT ASSEMBLY SEAT FRONT | D25: BF182634 | E25: 1
B26: فيبرة حزام خلفى يمين | C26: SEAT BELT ELR REAR COVER RH | D26: BF182624 | E26: 1
B27: فيبرة حزام خلفى شمال | C27: SEAT BELT ELR REAR COVER LH | D27: BF182625 | E27: 1
A28: 13 | B28: فبرة مثلث يمين | E28: 1
A29: 13 | B29: فبرة مثلث شمال | E29: 1
A30: 14 | B30: باب خلفي يمين كامل + فريم + فبرة زجاج + جوانة | C30: ASSEMBLY REAR DOOR COMP RH WHITE | D30: 52BF0102 | E30: 1
A31: 15 | B31: باب خلفي شمال | F31: No assembled part code for it (the door is available but was damaged in an accident and a repair is being attempted)
A32: 16 | B32: كابترة خلفي يمين خلفي | C32: GUARD SPLASH REAR RH REAR | D32: BF185078 | E32: 1
A33: 17 | B33: كابترة خلفي شمال خلفي | C33: GUARD SPLASH REAR LH REAR | D33: BF185081 | E33: 1
A34: 18 | B34: اكصدام خلفي يمين | C34: BUMPER REAR LH | D34: BF182008 | E34: 1
B35: اكصدام خلفي شمال | C35: BUMPER REAR RH | D35: BF182009 | E35: 1
A36: 19 | B36: دلايه خلفي شمال | C36: MUDFLAP FRONT LH | D36: BF185072 | E36: 1
B37: دلايه خلفي يمين | C37: MUDFLAP REAR RH | D37: BF185068 | E37: 1
A38: 20 | B38: دلايه موتور شمال | C38: COVER SIDE LH CNG | D38: BF182591 | E38: 1
B39: دلايه موتور يمين | C39: COVER SIDE RH CNG | D39: BF182590 | E39: 1
A40: 21 | B40: مرايا شمال | C40: ORVM LH | D40: BF184637 | E40: 1
A41: 22 | B41: شبكة علوية | C41: Under repair | E41: 1
